Traceback (most recent call last):
  File "/usr/share/miniconda/lib/python3.8/site-packages/jupyter_cache/executors/utils.py", line 51, in single_nb_execution
    executenb(
  File "/usr/share/miniconda/lib/python3.8/site-packages/nbclient/client.py", line 1093, in execute
    return NotebookClient(nb=nb, resources=resources, km=km, **kwargs).execute()
  File "/usr/share/miniconda/lib/python3.8/site-packages/nbclient/util.py", line 84, in wrapped
    return just_run(coro(*args, **kwargs))
  File "/usr/share/miniconda/lib/python3.8/site-packages/nbclient/util.py", line 62, in just_run
    return loop.run_until_complete(coro)
  File "/usr/share/miniconda/lib/python3.8/asyncio/base_events.py", line 616, in run_until_complete
    return future.result()
  File "/usr/share/miniconda/lib/python3.8/site-packages/nbclient/client.py", line 559, in async_execute
    await self.async_execute_cell(
  File "/usr/share/miniconda/lib/python3.8/site-packages/nbclient/client.py", line 854, in async_execute_cell
    self._check_raise_for_error(cell, exec_reply)
  File "/usr/share/miniconda/lib/python3.8/site-packages/nbclient/client.py", line 756, in _check_raise_for_error
    raise CellExecutionError.from_cell_and_msg(cell, exec_reply_content)
nbclient.exceptions.CellExecutionError: An error occurred while executing the following cell:
------------------
import glob
import os
import urllib
import numpy as np

import intake
from intake_zenodo_fetcher import download_zenodo_files_for_entry
import matplotlib.pyplot as plt
import xmltodict
import cv2

import tempfile

import torch

import warnings
warnings.filterwarnings(action='ignore')

%matplotlib inline
------------------

[0;31m---------------------------------------------------------------------------[0m
[0;31mModuleNotFoundError[0m                       Traceback (most recent call last)
[0;32m/tmp/ipykernel_8787/3548410720.py[0m in [0;36m<module>[0;34m[0m
[1;32m      5[0m [0;34m[0m[0m
[1;32m      6[0m [0;32mimport[0m [0mintake[0m[0;34m[0m[0;34m[0m[0m
[0;32m----> 7[0;31m [0;32mfrom[0m [0mintake_zenodo_fetcher[0m [0;32mimport[0m [0mdownload_zenodo_files_for_entry[0m[0;34m[0m[0;34m[0m[0m
[0m[1;32m      8[0m [0;32mimport[0m [0mmatplotlib[0m[0;34m.[0m[0mpyplot[0m [0;32mas[0m [0mplt[0m[0;34m[0m[0;34m[0m[0m
[1;32m      9[0m [0;32mimport[0m [0mxmltodict[0m[0;34m[0m[0;34m[0m[0m

[0;31mModuleNotFoundError[0m: No module named 'intake_zenodo_fetcher'
ModuleNotFoundError: No module named 'intake_zenodo_fetcher'

