Traceback (most recent call last):
  File "/Users/ac/anaconda3/envs/envsensors/lib/python3.8/site-packages/jupyter_cache/executors/utils.py", line 51, in single_nb_execution
    executenb(
  File "/Users/ac/anaconda3/envs/envsensors/lib/python3.8/site-packages/nbclient/client.py", line 1112, in execute
    return NotebookClient(nb=nb, resources=resources, km=km, **kwargs).execute()
  File "/Users/ac/anaconda3/envs/envsensors/lib/python3.8/site-packages/nbclient/util.py", line 74, in wrapped
    return just_run(coro(*args, **kwargs))
  File "/Users/ac/anaconda3/envs/envsensors/lib/python3.8/site-packages/nbclient/util.py", line 53, in just_run
    return loop.run_until_complete(coro)
  File "/Users/ac/anaconda3/envs/envsensors/lib/python3.8/asyncio/base_events.py", line 616, in run_until_complete
    return future.result()
  File "/Users/ac/anaconda3/envs/envsensors/lib/python3.8/site-packages/nbclient/client.py", line 553, in async_execute
    await self.async_execute_cell(
  File "/Users/ac/anaconda3/envs/envsensors/lib/python3.8/site-packages/nbclient/client.py", line 857, in async_execute_cell
    self._check_raise_for_error(cell, exec_reply)
  File "/Users/ac/anaconda3/envs/envsensors/lib/python3.8/site-packages/nbclient/client.py", line 760, in _check_raise_for_error
    raise CellExecutionError.from_cell_and_msg(cell, exec_reply_content)
nbclient.exceptions.CellExecutionError: An error occurred while executing the following cell:
------------------
metadata.hvplot.points('lon', 'lat', geo=True, color='vegetation',
                       height=420, width=800, cmap='Category20') * gts.OSM
------------------

[0;31m---------------------------------------------------------------------------[0m
[0;31mNameError[0m                                 Traceback (most recent call last)
[0;32m<ipython-input-8-98577c7f8140>[0m in [0;36m<module>[0;34m[0m
[1;32m      1[0m metadata.hvplot.points('lon', 'lat', geo=True, color='vegetation',
[0;32m----> 2[0;31m                        height=420, width=800, cmap='Category20') * gts.OSM
[0m
[0;31mNameError[0m: name 'gts' is not defined
NameError: name 'gts' is not defined

