Traceback (most recent call last):
  File "/usr/share/miniconda/lib/python3.8/site-packages/jupyter_cache/executors/utils.py", line 51, in single_nb_execution
    executenb(
  File "/usr/share/miniconda/lib/python3.8/site-packages/nbclient/client.py", line 1093, in execute
    return NotebookClient(nb=nb, resources=resources, km=km, **kwargs).execute()
  File "/usr/share/miniconda/lib/python3.8/site-packages/nbclient/util.py", line 84, in wrapped
    return just_run(coro(*args, **kwargs))
  File "/usr/share/miniconda/lib/python3.8/site-packages/nbclient/util.py", line 62, in just_run
    return loop.run_until_complete(coro)
  File "/usr/share/miniconda/lib/python3.8/asyncio/base_events.py", line 616, in run_until_complete
    return future.result()
  File "/usr/share/miniconda/lib/python3.8/site-packages/nbclient/client.py", line 559, in async_execute
    await self.async_execute_cell(
  File "/usr/share/miniconda/lib/python3.8/site-packages/nbclient/client.py", line 854, in async_execute_cell
    self._check_raise_for_error(cell, exec_reply)
  File "/usr/share/miniconda/lib/python3.8/site-packages/nbclient/client.py", line 756, in _check_raise_for_error
    raise CellExecutionError.from_cell_and_msg(cell, exec_reply_content)
nbclient.exceptions.CellExecutionError: An error occurred while executing the following cell:
------------------
import cv2
from PIL import Image
import os
import numpy as np
import urllib.request
import glob

# intake library and plugin
import intake
from intake_zenodo_fetcher import download_zenodo_files_for_entry

# geospatial libraries
import geopandas as gpd

from rasterio.transform import from_origin
import rasterio.features

import fiona

from shapely.geometry import shape, mapping, box
from shapely.geometry.multipolygon import MultiPolygon

# machine learning libraries
from detectron2 import model_zoo
from detectron2.engine import DefaultPredictor
from detectron2.utils.visualizer import Visualizer, ColorMode
from detectron2.config import get_cfg
from detectron2.engine import DefaultTrainer

# visualisation
import holoviews as hv
from IPython.display import display
import geoviews.tile_sources as gts

import hvplot.pandas
import hvplot.xarray

import warnings
warnings.filterwarnings(action='ignore')

hv.extension('bokeh', width=100)
------------------

[0;31m---------------------------------------------------------------------------[0m
[0;31mModuleNotFoundError[0m                       Traceback (most recent call last)
[0;32m/tmp/ipykernel_8092/274128899.py[0m in [0;36m<module>[0;34m[0m
[1;32m      8[0m [0;31m# intake library and plugin[0m[0;34m[0m[0;34m[0m[0;34m[0m[0m
[1;32m      9[0m [0;32mimport[0m [0mintake[0m[0;34m[0m[0;34m[0m[0m
[0;32m---> 10[0;31m [0;32mfrom[0m [0mintake_zenodo_fetcher[0m [0;32mimport[0m [0mdownload_zenodo_files_for_entry[0m[0;34m[0m[0;34m[0m[0m
[0m[1;32m     11[0m [0;34m[0m[0m
[1;32m     12[0m [0;31m# geospatial libraries[0m[0;34m[0m[0;34m[0m[0;34m[0m[0m

[0;31mModuleNotFoundError[0m: No module named 'intake_zenodo_fetcher'
ModuleNotFoundError: No module named 'intake_zenodo_fetcher'

