Traceback (most recent call last):
  File "/Users/acoca/anaconda3/envs/envai-book/lib/python3.8/site-packages/jupyter_cache/executors/utils.py", line 51, in single_nb_execution
    executenb(
  File "/Users/acoca/anaconda3/envs/envai-book/lib/python3.8/site-packages/nbclient/client.py", line 1117, in execute
    return NotebookClient(nb=nb, resources=resources, km=km, **kwargs).execute()
  File "/Users/acoca/anaconda3/envs/envai-book/lib/python3.8/site-packages/nbclient/util.py", line 78, in wrapped
    return just_run(coro(*args, **kwargs))
  File "/Users/acoca/anaconda3/envs/envai-book/lib/python3.8/site-packages/nbclient/util.py", line 57, in just_run
    return loop.run_until_complete(coro)
  File "/Users/acoca/anaconda3/envs/envai-book/lib/python3.8/asyncio/base_events.py", line 616, in run_until_complete
    return future.result()
  File "/Users/acoca/anaconda3/envs/envai-book/lib/python3.8/site-packages/nbclient/client.py", line 558, in async_execute
    await self.async_execute_cell(
  File "/Users/acoca/anaconda3/envs/envai-book/lib/python3.8/site-packages/nbclient/client.py", line 862, in async_execute_cell
    self._check_raise_for_error(cell, exec_reply)
  File "/Users/acoca/anaconda3/envs/envai-book/lib/python3.8/site-packages/nbclient/client.py", line 765, in _check_raise_for_error
    raise CellExecutionError.from_cell_and_msg(cell, exec_reply_content)
nbclient.exceptions.CellExecutionError: An error occurred while executing the following cell:
------------------
# define the URL to retrieve the model
fn = 'model_final.pth'
url = f'https://zenodo.org/record/5515408/files/{fn}?download=1'

urllib.request.urlretrieve(url, config['model'] + '/' + fn)
------------------

[0;31m---------------------------------------------------------------------------[0m
[0;31mContentTooShortError[0m                      Traceback (most recent call last)
[0;32m/var/folders/l8/99_59fvn4bl2szm125grkgqw0000gr/T/ipykernel_6126/2414633227.py[0m in [0;36m<module>[0;34m[0m
[1;32m      3[0m [0murl[0m [0;34m=[0m [0;34mf'https://zenodo.org/record/5515408/files/{fn}?download=1'[0m[0;34m[0m[0;34m[0m[0m
[1;32m      4[0m [0;34m[0m[0m
[0;32m----> 5[0;31m [0murllib[0m[0;34m.[0m[0mrequest[0m[0;34m.[0m[0murlretrieve[0m[0;34m([0m[0murl[0m[0;34m,[0m [0mconfig[0m[0;34m[[0m[0;34m'model'[0m[0;34m][0m [0;34m+[0m [0;34m'/'[0m [0;34m+[0m [0mfn[0m[0;34m)[0m[0;34m[0m[0;34m[0m[0m
[0m
[0;32m~/anaconda3/envs/envai-book/lib/python3.8/urllib/request.py[0m in [0;36murlretrieve[0;34m(url, filename, reporthook, data)[0m
[1;32m    284[0m [0;34m[0m[0m
[1;32m    285[0m     [0;32mif[0m [0msize[0m [0;34m>=[0m [0;36m0[0m [0;32mand[0m [0mread[0m [0;34m<[0m [0msize[0m[0;34m:[0m[0;34m[0m[0;34m[0m[0m
[0;32m--> 286[0;31m         raise ContentTooShortError(
[0m[1;32m    287[0m             [0;34m"retrieval incomplete: got only %i out of %i bytes"[0m[0;34m[0m[0;34m[0m[0m
[1;32m    288[0m             % (read, size), result)

[0;31mContentTooShortError[0m: <urlopen error retrieval incomplete: got only 40893439 out of 252492977 bytes>
ContentTooShortError: <urlopen error retrieval incomplete: got only 40893439 out of 252492977 bytes>

