Traceback (most recent call last):
  File "/Users/acoca/anaconda3/envs/envai-book/lib/python3.8/site-packages/jupyter_cache/executors/utils.py", line 51, in single_nb_execution
    executenb(
  File "/Users/acoca/anaconda3/envs/envai-book/lib/python3.8/site-packages/nbclient/client.py", line 1117, in execute
    return NotebookClient(nb=nb, resources=resources, km=km, **kwargs).execute()
  File "/Users/acoca/anaconda3/envs/envai-book/lib/python3.8/site-packages/nbclient/util.py", line 78, in wrapped
    return just_run(coro(*args, **kwargs))
  File "/Users/acoca/anaconda3/envs/envai-book/lib/python3.8/site-packages/nbclient/util.py", line 57, in just_run
    return loop.run_until_complete(coro)
  File "/Users/acoca/anaconda3/envs/envai-book/lib/python3.8/asyncio/base_events.py", line 616, in run_until_complete
    return future.result()
  File "/Users/acoca/anaconda3/envs/envai-book/lib/python3.8/site-packages/nbclient/client.py", line 558, in async_execute
    await self.async_execute_cell(
  File "/Users/acoca/anaconda3/envs/envai-book/lib/python3.8/site-packages/nbclient/client.py", line 862, in async_execute_cell
    self._check_raise_for_error(cell, exec_reply)
  File "/Users/acoca/anaconda3/envs/envai-book/lib/python3.8/site-packages/nbclient/client.py", line 765, in _check_raise_for_error
    raise CellExecutionError.from_cell_and_msg(cell, exec_reply_content)
nbclient.exceptions.CellExecutionError: An error occurred while executing the following cell:
------------------
air_temp = iris.load_cube(notebook_folder, filename)
air_temp.coord('grid_latitude').guess_bounds()
air_temp.coord('grid_longitude').guess_bounds()
------------------

[0;31m---------------------------------------------------------------------------[0m
[0;31mIsADirectoryError[0m                         Traceback (most recent call last)
[0;32m/var/folders/l8/99_59fvn4bl2szm125grkgqw0000gr/T/ipykernel_5031/624212618.py[0m in [0;36m<module>[0;34m[0m
[0;32m----> 1[0;31m [0mair_temp[0m [0;34m=[0m [0miris[0m[0;34m.[0m[0mload_cube[0m[0;34m([0m[0mnotebook_folder[0m[0;34m,[0m [0mfilename[0m[0;34m)[0m[0;34m[0m[0;34m[0m[0m
[0m[1;32m      2[0m [0mair_temp[0m[0;34m.[0m[0mcoord[0m[0;34m([0m[0;34m'grid_latitude'[0m[0;34m)[0m[0;34m.[0m[0mguess_bounds[0m[0;34m([0m[0;34m)[0m[0;34m[0m[0;34m[0m[0m
[1;32m      3[0m [0mair_temp[0m[0;34m.[0m[0mcoord[0m[0;34m([0m[0;34m'grid_longitude'[0m[0;34m)[0m[0;34m.[0m[0mguess_bounds[0m[0;34m([0m[0;34m)[0m[0;34m[0m[0;34m[0m[0m

[0;32m~/anaconda3/envs/envai-book/lib/python3.8/site-packages/iris/__init__.py[0m in [0;36mload_cube[0;34m(uris, constraint, callback)[0m
[1;32m    332[0m         [0;32mraise[0m [0mValueError[0m[0;34m([0m[0;34m"only a single constraint is allowed"[0m[0;34m)[0m[0;34m[0m[0;34m[0m[0m
[1;32m    333[0m [0;34m[0m[0m
[0;32m--> 334[0;31m     [0mcubes[0m [0;34m=[0m [0m_load_collection[0m[0;34m([0m[0muris[0m[0;34m,[0m [0mconstraints[0m[0;34m,[0m [0mcallback[0m[0;34m)[0m[0;34m.[0m[0mcubes[0m[0;34m([0m[0;34m)[0m[0;34m[0m[0;34m[0m[0m
[0m[1;32m    335[0m [0;34m[0m[0m
[1;32m    336[0m     [0;32mtry[0m[0;34m:[0m[0;34m[0m[0;34m[0m[0m

[0;32m~/anaconda3/envs/envai-book/lib/python3.8/site-packages/iris/__init__.py[0m in [0;36m_load_collection[0;34m(uris, constraints, callback)[0m
[1;32m    269[0m     [0;32mtry[0m[0;34m:[0m[0;34m[0m[0;34m[0m[0m
[1;32m    270[0m         [0mcubes[0m [0;34m=[0m [0m_generate_cubes[0m[0;34m([0m[0muris[0m[0;34m,[0m [0mcallback[0m[0;34m,[0m [0mconstraints[0m[0;34m)[0m[0;34m[0m[0;34m[0m[0m
[0;32m--> 271[0;31m         [0mresult[0m [0;34m=[0m [0miris[0m[0;34m.[0m[0mcube[0m[0;34m.[0m[0m_CubeFilterCollection[0m[0;34m.[0m[0mfrom_cubes[0m[0;34m([0m[0mcubes[0m[0;34m,[0m [0mconstraints[0m[0;34m)[0m[0;34m[0m[0;34m[0m[0m
[0m[1;32m    272[0m     [0;32mexcept[0m [0mEOFError[0m [0;32mas[0m [0me[0m[0;34m:[0m[0;34m[0m[0;34m[0m[0m
[1;32m    273[0m         raise iris.exceptions.TranslationError(

[0;32m~/anaconda3/envs/envai-book/lib/python3.8/site-packages/iris/cube.py[0m in [0;36mfrom_cubes[0;34m(cubes, constraints)[0m
[1;32m    115[0m         [0mpairs[0m [0;34m=[0m [0;34m[[0m[0m_CubeFilter[0m[0;34m([0m[0mconstraint[0m[0;34m)[0m [0;32mfor[0m [0mconstraint[0m [0;32min[0m [0mconstraints[0m[0;34m][0m[0;34m[0m[0;34m[0m[0m
[1;32m    116[0m         [0mcollection[0m [0;34m=[0m [0m_CubeFilterCollection[0m[0;34m([0m[0mpairs[0m[0;34m)[0m[0;34m[0m[0;34m[0m[0m
[0;32m--> 117[0;31m         [0;32mfor[0m [0mcube[0m [0;32min[0m [0mcubes[0m[0;34m:[0m[0;34m[0m[0;34m[0m[0m
[0m[1;32m    118[0m             [0mcollection[0m[0;34m.[0m[0madd_cube[0m[0;34m([0m[0mcube[0m[0;34m)[0m[0;34m[0m[0;34m[0m[0m
[1;32m    119[0m         [0;32mreturn[0m [0mcollection[0m[0;34m[0m[0;34m[0m[0m

[0;32m~/anaconda3/envs/envai-book/lib/python3.8/site-packages/iris/__init__.py[0m in [0;36m_generate_cubes[0;34m(uris, callback, constraints)[0m
[1;32m    256[0m         [0;32mif[0m [0mscheme[0m [0;34m==[0m [0;34m"file"[0m[0;34m:[0m[0;34m[0m[0;34m[0m[0m
[1;32m    257[0m             [0mpart_names[0m [0;34m=[0m [0;34m[[0m[0mx[0m[0;34m[[0m[0;36m1[0m[0;34m][0m [0;32mfor[0m [0mx[0m [0;32min[0m [0mgroups[0m[0;34m][0m[0;34m[0m[0;34m[0m[0m
[0;32m--> 258[0;31m             [0;32mfor[0m [0mcube[0m [0;32min[0m [0miris[0m[0;34m.[0m[0mio[0m[0;34m.[0m[0mload_files[0m[0;34m([0m[0mpart_names[0m[0;34m,[0m [0mcallback[0m[0;34m,[0m [0mconstraints[0m[0;34m)[0m[0;34m:[0m[0;34m[0m[0;34m[0m[0m
[0m[1;32m    259[0m                 [0;32myield[0m [0mcube[0m[0;34m[0m[0;34m[0m[0m
[1;32m    260[0m         [0;32melif[0m [0mscheme[0m [0;32min[0m [0;34m[[0m[0;34m"http"[0m[0;34m,[0m [0;34m"https"[0m[0;34m][0m[0;34m:[0m[0;34m[0m[0;34m[0m[0m

[0;32m~/anaconda3/envs/envai-book/lib/python3.8/site-packages/iris/io/__init__.py[0m in [0;36mload_files[0;34m(filenames, callback, constraints)[0m
[1;32m    190[0m     [0mhandler_map[0m [0;34m=[0m [0mcollections[0m[0;34m.[0m[0mdefaultdict[0m[0;34m([0m[0mlist[0m[0;34m)[0m[0;34m[0m[0;34m[0m[0m
[1;32m    191[0m     [0;32mfor[0m [0mfn[0m [0;32min[0m [0mall_file_paths[0m[0;34m:[0m[0;34m[0m[0;34m[0m[0m
[0;32m--> 192[0;31m         [0;32mwith[0m [0mopen[0m[0;34m([0m[0mfn[0m[0;34m,[0m [0;34m"rb"[0m[0;34m)[0m [0;32mas[0m [0mfh[0m[0;34m:[0m[0;34m[0m[0;34m[0m[0m
[0m[1;32m    193[0m             handling_format_spec = iris.fileformats.FORMAT_AGENT.get_spec(
[1;32m    194[0m                 [0mos[0m[0;34m.[0m[0mpath[0m[0;34m.[0m[0mbasename[0m[0;34m([0m[0mfn[0m[0;34m)[0m[0;34m,[0m [0mfh[0m[0;34m[0m[0;34m[0m[0m

[0;31mIsADirectoryError[0m: [Errno 21] Is a directory: '/Users/acoca/OneDrive - The Alan Turing Institute/Documents/projects/envsensors/wp3/repos/environmental-ai-book/book/urban/sensors/urban-sensors-climate_ukv'
IsADirectoryError: [Errno 21] Is a directory: '/Users/acoca/OneDrive - The Alan Turing Institute/Documents/projects/envsensors/wp3/repos/environmental-ai-book/book/urban/sensors/urban-sensors-climate_ukv'

