Traceback (most recent call last):
  File "/Users/acoca/anaconda3/envs/envai-book/lib/python3.8/site-packages/jupyter_cache/executors/utils.py", line 51, in single_nb_execution
    executenb(
  File "/Users/acoca/anaconda3/envs/envai-book/lib/python3.8/site-packages/nbclient/client.py", line 1117, in execute
    return NotebookClient(nb=nb, resources=resources, km=km, **kwargs).execute()
  File "/Users/acoca/anaconda3/envs/envai-book/lib/python3.8/site-packages/nbclient/util.py", line 78, in wrapped
    return just_run(coro(*args, **kwargs))
  File "/Users/acoca/anaconda3/envs/envai-book/lib/python3.8/site-packages/nbclient/util.py", line 57, in just_run
    return loop.run_until_complete(coro)
  File "/Users/acoca/anaconda3/envs/envai-book/lib/python3.8/asyncio/base_events.py", line 616, in run_until_complete
    return future.result()
  File "/Users/acoca/anaconda3/envs/envai-book/lib/python3.8/site-packages/nbclient/client.py", line 558, in async_execute
    await self.async_execute_cell(
  File "/Users/acoca/anaconda3/envs/envai-book/lib/python3.8/site-packages/nbclient/client.py", line 862, in async_execute_cell
    self._check_raise_for_error(cell, exec_reply)
  File "/Users/acoca/anaconda3/envs/envai-book/lib/python3.8/site-packages/nbclient/client.py", line 765, in _check_raise_for_error
    raise CellExecutionError.from_cell_and_msg(cell, exec_reply_content)
nbclient.exceptions.CellExecutionError: An error occurred while executing the following cell:
------------------
fname = 'MOD021KM.A2020245.0840.061.2020245193036.hdf'

if not os.path.isfile(fname) or os.path.getsize(fname) == 0:
    username = input('Username: ')
    password = getpass('Password: ')

    fsspec.config.conf['https'] = dict(client_kwargs={'auth': aiohttp.BasicAuth(username, password)})

    url = f'https://ladsweb.modaps.eosdis.nasa.gov/archive/allData/61/MOD021KM/2020/245/{fname}'
    filename = url.split('/')[-1]
    with fsspec.open(url) as f:
        with Path(filename).open('wb') as handle:
            data = f.read()
            try:
                data.decode('utf-8')
                raise RuntimeError('Could not download MODIS data! Have you authorized LAADS Web in your Eathdata account above?')
            except UnicodeDecodeError:
                handle.write(data)
------------------

[0;31m---------------------------------------------------------------------------[0m
[0;31mStdinNotImplementedError[0m                  Traceback (most recent call last)
[0;32m/var/folders/l8/99_59fvn4bl2szm125grkgqw0000gr/T/ipykernel_4620/4139613018.py[0m in [0;36m<module>[0;34m[0m
[1;32m      2[0m [0;34m[0m[0m
[1;32m      3[0m [0;32mif[0m [0;32mnot[0m [0mos[0m[0;34m.[0m[0mpath[0m[0;34m.[0m[0misfile[0m[0;34m([0m[0mfname[0m[0;34m)[0m [0;32mor[0m [0mos[0m[0;34m.[0m[0mpath[0m[0;34m.[0m[0mgetsize[0m[0;34m([0m[0mfname[0m[0;34m)[0m [0;34m==[0m [0;36m0[0m[0;34m:[0m[0;34m[0m[0;34m[0m[0m
[0;32m----> 4[0;31m     [0musername[0m [0;34m=[0m [0minput[0m[0;34m([0m[0;34m'Username: '[0m[0;34m)[0m[0;34m[0m[0;34m[0m[0m
[0m[1;32m      5[0m     [0mpassword[0m [0;34m=[0m [0mgetpass[0m[0;34m([0m[0;34m'Password: '[0m[0;34m)[0m[0;34m[0m[0;34m[0m[0m
[1;32m      6[0m [0;34m[0m[0m

[0;32m~/anaconda3/envs/envai-book/lib/python3.8/site-packages/ipykernel/kernelbase.py[0m in [0;36mraw_input[0;34m(self, prompt)[0m
[1;32m   1001[0m         """
[1;32m   1002[0m         [0;32mif[0m [0;32mnot[0m [0mself[0m[0;34m.[0m[0m_allow_stdin[0m[0;34m:[0m[0;34m[0m[0;34m[0m[0m
[0;32m-> 1003[0;31m             raise StdinNotImplementedError(
[0m[1;32m   1004[0m                 [0;34m"raw_input was called, but this frontend does not support input requests."[0m[0;34m[0m[0;34m[0m[0m
[1;32m   1005[0m             )

[0;31mStdinNotImplementedError[0m: raw_input was called, but this frontend does not support input requests.
StdinNotImplementedError: raw_input was called, but this frontend does not support input requests.

