Traceback (most recent call last):
  File "/usr/share/miniconda/lib/python3.8/site-packages/jupyter_cache/executors/utils.py", line 51, in single_nb_execution
    executenb(
  File "/usr/share/miniconda/lib/python3.8/site-packages/nbclient/client.py", line 1093, in execute
    return NotebookClient(nb=nb, resources=resources, km=km, **kwargs).execute()
  File "/usr/share/miniconda/lib/python3.8/site-packages/nbclient/util.py", line 84, in wrapped
    return just_run(coro(*args, **kwargs))
  File "/usr/share/miniconda/lib/python3.8/site-packages/nbclient/util.py", line 62, in just_run
    return loop.run_until_complete(coro)
  File "/usr/share/miniconda/lib/python3.8/asyncio/base_events.py", line 616, in run_until_complete
    return future.result()
  File "/usr/share/miniconda/lib/python3.8/site-packages/nbclient/client.py", line 559, in async_execute
    await self.async_execute_cell(
  File "/usr/share/miniconda/lib/python3.8/site-packages/nbclient/client.py", line 854, in async_execute_cell
    self._check_raise_for_error(cell, exec_reply)
  File "/usr/share/miniconda/lib/python3.8/site-packages/nbclient/client.py", line 756, in _check_raise_for_error
    raise CellExecutionError.from_cell_and_msg(cell, exec_reply_content)
nbclient.exceptions.CellExecutionError: An error occurred while executing the following cell:
------------------
import pandas as pd
import numpy as np
import geopandas
import intake
import fsspec, aiohttp
import hvplot.xarray
import hvplot.pandas
import holoviews as hv
import panel as pn
import satpy
import xarray as xr
import tempfile
from scipy.spatial import cKDTree
from satpy.writers import get_enhanced_image
from getpass import getpass
from pathlib import Path
from pyresample import geometry
from pyresample import create_area_def
import datetime
import urllib.request
import os.path
import requests
from pathlib import Path
import warnings
warnings.filterwarnings(action='ignore')
------------------

[0;31m---------------------------------------------------------------------------[0m
[0;31mModuleNotFoundError[0m                       Traceback (most recent call last)
[0;32m/tmp/ipykernel_10949/445254910.py[0m in [0;36m<module>[0;34m[0m
[1;32m      1[0m [0;32mimport[0m [0mpandas[0m [0;32mas[0m [0mpd[0m[0;34m[0m[0;34m[0m[0m
[1;32m      2[0m [0;32mimport[0m [0mnumpy[0m [0;32mas[0m [0mnp[0m[0;34m[0m[0;34m[0m[0m
[0;32m----> 3[0;31m [0;32mimport[0m [0mgeopandas[0m[0;34m[0m[0;34m[0m[0m
[0m[1;32m      4[0m [0;32mimport[0m [0mintake[0m[0;34m[0m[0;34m[0m[0m
[1;32m      5[0m [0;32mimport[0m [0mfsspec[0m[0;34m,[0m [0maiohttp[0m[0;34m[0m[0;34m[0m[0m

[0;31mModuleNotFoundError[0m: No module named 'geopandas'
ModuleNotFoundError: No module named 'geopandas'

